<?xml version="1.0"?>
<robot name="sirdigsalot">
  <link name="base_link">
    <visual>
      <geometry>
        <box size=".4572 .8636 .1"/>
      </geometry>
    </visual>
    <collision>
      <geometry>
        <box size=".4572 .8636 .1"/>
      </geometry>
    </collision>
    <inertial>
      <mass value="1"/>
      <inertia
        ixx="0.0" ixy="0.0" ixz="0.0"
        iyy="0.0" iyz="0.0"
        izz="0.0"/>
    </inertial>
  </link>

  <link name="right_front_wheel">
    <visual>
      <geometry>
        <cylinder length=".0635" radius="0.1016"/>
      </geometry>
      <origin rpy="0 1.57075 0"/>
    </visual>
    <collision>
      <geometry>
        <cylinder length=".0635" radius="0.1016"/>
      </geometry>
      <origin rpy="0 1.57075 0"/>
    </collision>
    <inertial>
      <origin rpy="0 1.57075  0"/>
      <mass value="1"/>
      <inertia
        ixx="0.0" ixy="0.0" ixz="0.0"
        iyy="0.0" iyz="0.0"
        izz="0.0"/>
    </inertial>
  </link>

  <link name="left_front_wheel">
    <visual>
      <geometry>
        <cylinder length=".0635" radius="0.1016"/>
      </geometry>
      <origin rpy="0 1.57075 0"/>
    </visual>
    <collision>
      <geometry>
        <cylinder length=".0635" radius="0.1016"/>
      </geometry>
      <origin rpy="0 1.57075 0"/>
    </collision>
    <inertial>
      <origin rpy="0 1.57075 0"/>
      <mass value="1"/>
      <inertia
        ixx="0.0" ixy="0.0" ixz="0.0"
        iyy="0.0" iyz="0.0"
        izz="0.0"/>
    </inertial>
  </link>

  <link name="right_back_wheel">
    <visual>
      <geometry>
        <cylinder length=".0635" radius="0.1016"/>
      </geometry>
      <origin rpy="0 1.57075 0"/>
    </visual>
    <collision>
      <geometry>
        <cylinder length=".0635" radius="0.1016"/>
      </geometry>
      <origin rpy="0 1.57075 0"/>
    </collision>
    <inertial>
      <origin rpy="0 1.57075 0"/>
      <mass value="1"/>
      <inertia
        ixx="0.0" ixy="0.0" ixz="0.0"
        iyy="0.0" iyz="0.0"
        izz="0.0"/>
    </inertial>
  </link>

  <link name="left_back_wheel">
    <visual>
      <geometry>
        <cylinder length=".0635" radius="0.1016"/>
      </geometry>
      <origin rpy="0 1.57075 0"/>
    </visual>
    <collision>
      <geometry>
        <cylinder length=".0635" radius="0.1016"/>
      </geometry>
      <origin rpy="0 1.57075 0"/>
    </collision>
    <inertial>
      <origin rpy="0 1.57075 0"/>
      <mass value="1"/>
      <inertia
        ixx="0.0" ixy="0.0" ixz="0.0"
        iyy="0.0" iyz="0.0"
        izz="0.0"/>
    </inertial>
  </link>

  <joint name="rf_wheel_joint" type="continuous">
    <parent link="base_link"/>
    <child link="right_front_wheel"/>
    <axis xyz="1 0 0"/>
    <origin xyz=".2667 .365125 0"/>
    <dynamics damping="0.2" friction="0.0"/>
  </joint>

  <joint name="lf_wheel_joint" type="continuous">
    <parent link="base_link"/>
    <child link="left_front_wheel"/>
    <axis xyz="1 0 0"/>
    <origin xyz="-.2667 .365125 0"/>
    <dynamics damping="0.2" friction="0.0"/>
  </joint>

  <joint name="rb_wheel_joint" type="continuous">
    <parent link="base_link"/>
    <child link="right_back_wheel"/>
    <axis xyz="1 0 0"/>
    <origin xyz=".2667 -.365125 0"/>
    <dynamics damping="0.2" friction="0.0"/>
  </joint>

  <joint name="lb_wheel_joint" type="continuous">
    <parent link="base_link"/>
    <child link="left_back_wheel"/>
    <axis xyz="1 0 0"/>
    <origin xyz="-.2667 -.365125 0"/>
    <dynamics damping="0.2" friction="0.0"/>
  </joint>

  <!-- gazebosim.org/tutorials?tut=ros_control&cat=control_ros -->
  <transmission name="rf_transmission">
    <type>transmission_interface/SimpleTransmission</type>
    <actuator name="rf_wheel_joint_motor">
      <mechanicalReduction>1</mechanicalReduction>
    </actuator>
    <joint name="rf_wheel_joint">
      <hardwareInterface>hardware_interface/VelocityJointInterface</hardwareInterface>
    </joint>
  </transmission>

  <transmission name="lf_transmission">
    <type>transmission_interface/SimpleTransmission</type>
    <actuator name="lf_wheel_joint_motor">
      <mechanicalReduction>1</mechanicalReduction>
    </actuator>
    <joint name="lf_wheel_joint">
      <hardwareInterface>hardware_interface/VelocityJointInterface</hardwareInterface>
    </joint>
  </transmission>

  <transmission name="rb_transmission">
    <type>transmission_interface/SimpleTransmission</type>
    <actuator name="rb_wheel_joint_motor">
      <mechanicalReduction>1</mechanicalReduction>
    </actuator>
    <joint name="rb_wheel_joint">
      <hardwareInterface>hardware_interface/VelocityJointInterface</hardwareInterface>
    </joint>
  </transmission>

  <transmission name="lb_transmission">
    <type>transmission_interface/SimpleTransmission</type>
    <actuator name="lb_wheel_joint_motor">
      <mechanicalReduction>1</mechanicalReduction>
    </actuator>
    <joint name="lb_wheel_joint">
      <hardwareInterface>hardware_interface/VelocityJointInterface</hardwareInterface>
    </joint>
  </transmission>


  <!-- fake joints because the virtual actuator joints need children -->
  <link name="dump_end">
  </link>
  <link name="ladder_end">
  </link>

  <joint name="dump" type="prismatic">
    <parent link="base_link"/>
    <child link="dump_end"/>
    <limit upper="0.20" effort="90" velocity="1000"/>
  </joint>
  <joint name="ladder" type="prismatic">
    <parent link="base_link"/>
    <child link="ladder_end"/>
    <limit upper="0.20" effort="90" velocity="1000"/>
  </joint>

  <!-- http://gazebosim.org/tutorials?tut=ros_gzplugins -->
  <gazebo>
    <!--
    <plugin name="imu_plugin" filename="libgazebo_ros_imu.so">
      <robotNamespace>/sirdigsalot</robotNamespace>
      <alwaysOn>true</alwaysOn>
      <bodyName>base_link</bodyName>
      <topicName>imu</topicName>
      <serviceName>imu_service</serviceName>
      <gaussianNoise>0.0</gaussianNoise>
      <updateRate>20.0</updateRate>
      <frameName>base_link</frameName>
    </plugin>
    -->
    <plugin name="gazebo_ros_control" filename="libgazebo_ros_control.so">
      <controlPeriod>0.02</controlPeriod>
      <robotNamespace>/sirdigsalot</robotNamespace>
    </plugin>
  </gazebo>

</robot>
