<robot
  name="ROSModel">
  <link
    name="base_link">
    <inertial>
      <origin
        xyz="0.0063713 -0.11708 0.0018811"
        rpy="0 0 0" />
      <mass
        value="12.883" />
      <inertia
        ixx="0.27816"
        ixy="-0.020687"
        ixz="1.9963E-05"
        iyy="0.59209"
        iyz="3.0096E-05"
        izz="0.60601" />
    </inertial>
    <visual>
      <origin
        xyz="0 0 0"
        rpy="0 0 0" />
      <geometry>
        <mesh
          filename="package://ROSModel/meshes/base_link.STL" />
      </geometry>
      <material
        name="">
        <color
          rgba="0.79216 0.81961 0.93333 1" />
      </material>
    </visual>
    <collision>
      <origin
        xyz="0 0 0"
        rpy="0 0 0" />
      <geometry>
        <mesh
          filename="package://ROSModel/meshes/base_link.STL" />
      </geometry>
    </collision>
  </link>
  <link
    name="frontLeftWheel">
    <inertial>
      <origin
        xyz="0 0 -0.0508"
        rpy="0 0 0" />
      <mass
        value="7.4005" />
      <inertia
        ixx="0"
        ixy="0"
        ixz="0"
        iyy="0"
        iyz="0"
        izz="0" />
    </inertial>
    <visual>
      <origin
        xyz="0 0 0"
        rpy="0 0 0" />
      <geometry>
        <mesh
          filename="package://ROSModel/meshes/frontLeftWheel.STL" />
      </geometry>
      <material
        name="">
        <color
          rgba="0.79216 0.81961 0.93333 1" />
      </material>
    </visual>
    <collision>
      <origin
        xyz="0 0 0"
        rpy="0 0 0" />
      <geometry>
        <mesh
          filename="package://ROSModel/meshes/frontLeftWheel.STL" />
      </geometry>
    </collision>
  </link>
  <joint
    name="frontLeftWheelRotate"
    type="continuous">
    <origin
      xyz="0.30464 0.23782 -0.28624"
      rpy="1.5708 0.0022295 -1.3651E-19" />
    <parent
      link="base_link" />
    <child
      link="frontLeftWheel" />
    <axis
      xyz="0 0 1" />
  </joint>
  <link
    name="backLeftWheel">
    <inertial>
      <origin
        xyz="-1.6653E-16 -1.9602E-16 -0.0508"
        rpy="0 0 0" />
      <mass
        value="7.4005" />
      <inertia
        ixx="0"
        ixy="0"
        ixz="0"
        iyy="0"
        iyz="0"
        izz="0" />
    </inertial>
    <visual>
      <origin
        xyz="0 0 0"
        rpy="0 0 0" />
      <geometry>
        <mesh
          filename="package://ROSModel/meshes/backLeftWheel.STL" />
      </geometry>
      <material
        name="">
        <color
          rgba="0.79216 0.81961 0.93333 1" />
      </material>
    </visual>
    <collision>
      <origin
        xyz="0 0 0"
        rpy="0 0 0" />
      <geometry>
        <mesh
          filename="package://ROSModel/meshes/backLeftWheel.STL" />
      </geometry>
    </collision>
  </link>
  <joint
    name="backLeftWheelRotate"
    type="continuous">
    <origin
      xyz="-0.30496 0.23782 -0.28624"
      rpy="1.5708 -0.71925 -3.6358E-15" />
    <parent
      link="base_link" />
    <child
      link="backLeftWheel" />
    <axis
      xyz="0 0 1" />
  </joint>
  <link
    name="frontRightWheel">
    <inertial>
      <origin
        xyz="0 0 0.0508"
        rpy="0 0 0" />
      <mass
        value="7.4005" />
      <inertia
        ixx="0"
        ixy="0"
        ixz="0"
        iyy="0"
        iyz="0"
        izz="0" />
    </inertial>
    <visual>
      <origin
        xyz="0 0 0"
        rpy="0 0 0" />
      <geometry>
        <mesh
          filename="package://ROSModel/meshes/frontRightWheel.STL" />
      </geometry>
      <material
        name="">
        <color
          rgba="0.79216 0.81961 0.93333 1" />
      </material>
    </visual>
    <collision>
      <origin
        xyz="0 0 0"
        rpy="0 0 0" />
      <geometry>
        <mesh
          filename="package://ROSModel/meshes/frontRightWheel.STL" />
      </geometry>
    </collision>
  </link>
  <joint
    name="frontRightWheelRotate"
    type="continuous">
    <origin
      xyz="0.30464 -0.2416 -0.28624"
      rpy="1.5708 -0.055957 3.4299E-18" />
    <parent
      link="base_link" />
    <child
      link="frontRightWheel" />
    <axis
      xyz="0 0 1" />
  </joint>
  <link
    name="backRightWheel">
    <inertial>
      <origin
        xyz="5.55111512312578E-17 0 0.0508"
        rpy="0 0 0" />
      <mass
        value="7.40046273221895" />
      <inertia
        ixx="0"
        ixy="0"
        ixz="0"
        iyy="0"
        iyz="0"
        izz="0" />
    </inertial>
    <visual>
      <origin
        xyz="0 0 0"
        rpy="0 0 0" />
      <geometry>
        <mesh
          filename="package://ROSModel/meshes/backRightWheel.STL" />
      </geometry>
      <material
        name="">
        <color
          rgba="0.792156862745098 0.819607843137255 0.933333333333333 1" />
      </material>
    </visual>
    <collision>
      <origin
        xyz="0 0 0"
        rpy="0 0 0" />
      <geometry>
        <mesh
          filename="package://ROSModel/meshes/backRightWheel.STL" />
      </geometry>
    </collision>
  </link>
  <joint
    name="backRightWheelRotate"
    type="continuous">
    <origin
      xyz="-0.30496 -0.2416 -0.28624"
      rpy="1.5708 0 0" />
    <parent
      link="base_link" />
    <child
      link="backRightWheel" />
    <axis
      xyz="0 0 1" />
  </joint>
  <link
    name="depRightActuator">
    <inertial>
      <origin
        xyz="-4.2562E-09 -0.020725 3.5813E-09"
        rpy="0 0 0" />
      <mass
        value="0.088669" />
      <inertia
        ixx="0"
        ixy="0"
        ixz="0"
        iyy="0"
        iyz="0"
        izz="0" />
    </inertial>
    <visual>
      <origin
        xyz="0 0 0"
        rpy="0 0 0" />
      <geometry>
        <mesh
          filename="package://ROSModel/meshes/depRightActuator.STL" />
      </geometry>
      <material
        name="">
        <color
          rgba="0.79216 0.81961 0.93333 1" />
      </material>
    </visual>
    <collision>
      <origin
        xyz="0 0 0"
        rpy="0 0 0" />
      <geometry>
        <mesh
          filename="package://ROSModel/meshes/depRightActuator.STL" />
      </geometry>
    </collision>
  </link>
  <joint
    name="depRightExtend"
    type="prismatic">
    <origin
      xyz="-0.11281 -0.18528 0"
      rpy="-1.5708 0 0" />
    <parent
      link="base_link" />
    <child
      link="depRightActuator" />
    <axis
      xyz="0 -1 0" />
    <limit
      effort="0"
      velocity="0" />
  </joint>
  <link
    name="depConveyor">
    <inertial>
      <origin
        xyz="0.28997 -6.0219E-05 0.15395"
        rpy="0 0 0" />
      <mass
        value="22.501" />
      <inertia
        ixx="0.039859"
        ixy="6.0953E-06"
        ixz="0.047728"
        iyy="0.097009"
        iyz="-5.0904E-06"
        izz="0.05715" />
    </inertial>
    <visual>
      <origin
        xyz="0 0 0"
        rpy="0 0 0" />
      <geometry>
        <mesh
          filename="package://ROSModel/meshes/depConveyor.STL" />
      </geometry>
      <material
        name="">
        <color
          rgba="0.79216 0.81961 0.93333 1" />
      </material>
    </visual>
    <collision>
      <origin
        xyz="0 0 0"
        rpy="0 0 0" />
      <geometry>
        <mesh
          filename="package://ROSModel/meshes/depConveyor.STL" />
      </geometry>
    </collision>
  </link>
  <joint
    name="depConveyorRotate"
    type="fixed">
    <origin
      xyz="-0.36547 -0.16157 0.32661"
      rpy="3.1416 0 0.48826" />
    <parent
      link="depRightActuator" />
    <child
      link="depConveyor" />
    <axis
      xyz="0 0 0" />
  </joint>
  <link
    name="depLeftActuator">
    <inertial>
      <origin
        xyz="-4.2562E-09 -0.020725 3.5813E-09"
        rpy="0 0 0" />
      <mass
        value="0.088669" />
      <inertia
        ixx="0"
        ixy="0"
        ixz="0"
        iyy="0"
        iyz="0"
        izz="0" />
    </inertial>
    <visual>
      <origin
        xyz="0 0 0"
        rpy="0 0 0" />
      <geometry>
        <mesh
          filename="package://ROSModel/meshes/depLeftActuator.STL" />
      </geometry>
      <material
        name="">
        <color
          rgba="0.79216 0.81961 0.93333 1" />
      </material>
    </visual>
    <collision>
      <origin
        xyz="0 0 0"
        rpy="0 0 0" />
      <geometry>
        <mesh
          filename="package://ROSModel/meshes/depLeftActuator.STL" />
      </geometry>
    </collision>
  </link>
  <joint
    name="depLeftExtend"
    type="prismatic">
    <origin
      xyz="-0.11281 0.1815 0"
      rpy="-1.5708 6.3639E-19 3.1312" />
    <parent
      link="base_link" />
    <child
      link="depLeftActuator" />
    <axis
      xyz="0 -1 0" />
    <limit
      effort="0"
      velocity="0" />
  </joint>
  <link
    name="cameraActuator">
    <inertial>
      <origin
        xyz="-2.73470979195167E-09 0.124252406834887 -1.03760512334961E-09"
        rpy="0 0 0" />
      <mass
        value="0.210658735046211" />
      <inertia
        ixx="0"
        ixy="0"
        ixz="0"
        iyy="0"
        iyz="0"
        izz="0" />
    </inertial>
    <visual>
      <origin
        xyz="0 0 0"
        rpy="0 0 0" />
      <geometry>
        <mesh
          filename="package://ROSModel/meshes/cameraActuator.STL" />
      </geometry>
      <material
        name="">
        <color
          rgba="0.898039215686275 0.917647058823529 0.929411764705882 1" />
      </material>
    </visual>
    <collision>
      <origin
        xyz="0 0 0"
        rpy="0 0 0" />
      <geometry>
        <mesh
          filename="package://ROSModel/meshes/cameraActuator.STL" />
      </geometry>
    </collision>
  </link>
  <joint
    name="cameraExtend"
    type="prismatic">
    <origin
      xyz="0.41957 -0.0018055 0.0051623"
      rpy="1.5708 -3.9284E-18 -0.064201" />
    <parent
      link="base_link" />
    <child
      link="cameraActuator" />
    <axis
      xyz="0 1 0" />
    <limit
      effort="0"
      velocity="0" />
  </joint>
  <link
    name="intakeConveyor">
    <inertial>
      <origin
        xyz="-3.0286E-08 -0.0087509 0.085493"
        rpy="0 0 0" />
      <mass
        value="31.448" />
      <inertia
        ixx="0"
        ixy="0"
        ixz="0"
        iyy="0"
        iyz="0"
        izz="0" />
    </inertial>
    <visual>
      <origin
        xyz="0 0 0"
        rpy="0 0 0" />
      <geometry>
        <mesh
          filename="package://ROSModel/meshes/intakeConveyor.STL" />
      </geometry>
      <material
        name="">
        <color
          rgba="0.79216 0.81961 0.93333 1" />
      </material>
    </visual>
    <collision>
      <origin
        xyz="0 0 0"
        rpy="0 0 0" />
      <geometry>
        <mesh
          filename="package://ROSModel/meshes/intakeConveyor.STL" />
      </geometry>
    </collision>
  </link>
  <joint
    name="intakeExtend"
    type="prismatic">
    <origin
      xyz="0.25271 0.083601 0"
      rpy="1.5708 0 0" />
    <parent
      link="base_link" />
    <child
      link="intakeConveyor" />
    <axis
      xyz="0 1 0" />
    <limit
      lower="-0.54571"
      upper="0"
      effort="0"
      velocity="0" />
  </joint>
</robot>